Traceback (most recent call last):
  File "H:\HadiSadoghiYazdi\CircuitNew\Lib\site-packages\jupyter_cache\executors\utils.py", line 58, in single_nb_execution
    executenb(
    ~~~~~~~~~^
        nb,
        ^^^
    ...<4 lines>...
        **kwargs,
        ^^^^^^^^^
    )
    ^
  File "H:\HadiSadoghiYazdi\CircuitNew\Lib\site-packages\nbclient\client.py", line 1319, in execute
    return NotebookClient(nb=nb, resources=resources, km=km, **kwargs).execute()
           ~~~~~~~~~~~~~~~~~~~~~~~~~~~~~~~~~~~~~~~~~~~~~~~~~~~~~~~~~~~~~~~~~~~^^
  File "H:\HadiSadoghiYazdi\CircuitNew\Lib\site-packages\jupyter_core\utils\__init__.py", line 165, in wrapped
    return loop.run_until_complete(inner)
           ~~~~~~~~~~~~~~~~~~~~~~~^^^^^^^
  File "C:\Users\Hadi\AppData\Local\Programs\Python\Python313\Lib\asyncio\base_events.py", line 719, in run_until_complete
    return future.result()
           ~~~~~~~~~~~~~^^
  File "H:\HadiSadoghiYazdi\CircuitNew\Lib\site-packages\nbclient\client.py", line 709, in async_execute
    await self.async_execute_cell(
        cell, index, execution_count=self.code_cells_executed + 1
    )
  File "H:\HadiSadoghiYazdi\CircuitNew\Lib\site-packages\nbclient\client.py", line 1062, in async_execute_cell
    await self._check_raise_for_error(cell, cell_index, exec_reply)
  File "H:\HadiSadoghiYazdi\CircuitNew\Lib\site-packages\nbclient\client.py", line 918, in _check_raise_for_error
    raise CellExecutionError.from_cell_and_msg(cell, exec_reply_content)
nbclient.exceptions.CellExecutionError: An error occurred while executing the following cell:
------------------


import numpy as np
import matplotlib.pyplot as plt
import matplotlib.ticker as ticker


import PySpice.Logging.Logging as Logging
logger = Logging.setup_logging()


from PySpice.Doc.ExampleTools import find_libraries
from PySpice.Spice.Netlist import Circuit
from PySpice.Spice.Library import SpiceLibrary
from PySpice.Unit import *
from PySpice.Physics.SemiConductor import ShockleyDiode

spice_library = SpiceLibrary('.')
------------------


[31m---------------------------------------------------------------------------[39m
[31mModuleNotFoundError[39m                       Traceback (most recent call last)
[36mCell[39m[36m [39m[32mIn[1][39m[32m, line 6[39m
[32m      2[39m [38;5;28;01mimport[39;00m[38;5;250m [39m[34;01mmatplotlib[39;00m[34;01m.[39;00m[34;01mpyplot[39;00m[38;5;250m [39m[38;5;28;01mas[39;00m[38;5;250m [39m[34;01mplt[39;00m
[32m      3[39m [38;5;28;01mimport[39;00m[38;5;250m [39m[34;01mmatplotlib[39;00m[34;01m.[39;00m[34;01mticker[39;00m[38;5;250m [39m[38;5;28;01mas[39;00m[38;5;250m [39m[34;01mticker[39;00m
[32m----> [39m[32m6[39m [38;5;28;01mimport[39;00m[38;5;250m [39m[34;01mPySpice[39;00m[34;01m.[39;00m[34;01mLogging[39;00m[34;01m.[39;00m[34;01mLogging[39;00m[38;5;250m [39m[38;5;28;01mas[39;00m[38;5;250m [39m[34;01mLogging[39;00m
[32m      7[39m logger = Logging.setup_logging()
[32m     10[39m [38;5;28;01mfrom[39;00m[38;5;250m [39m[34;01mPySpice[39;00m[34;01m.[39;00m[34;01mDoc[39;00m[34;01m.[39;00m[34;01mExampleTools[39;00m[38;5;250m [39m[38;5;28;01mimport[39;00m find_libraries

[31mModuleNotFoundError[39m: No module named 'PySpice'

