Traceback (most recent call last):
  File "H:\HadiSadoghiYazdi\CircuitNew\Lib\site-packages\jupyter_cache\executors\utils.py", line 58, in single_nb_execution
    executenb(
    ~~~~~~~~~^
        nb,
        ^^^
    ...<4 lines>...
        **kwargs,
        ^^^^^^^^^
    )
    ^
  File "H:\HadiSadoghiYazdi\CircuitNew\Lib\site-packages\nbclient\client.py", line 1319, in execute
    return NotebookClient(nb=nb, resources=resources, km=km, **kwargs).execute()
           ~~~~~~~~~~~~~~~~~~~~~~~~~~~~~~~~~~~~~~~~~~~~~~~~~~~~~~~~~~~~~~~~~~~^^
  File "H:\HadiSadoghiYazdi\CircuitNew\Lib\site-packages\jupyter_core\utils\__init__.py", line 165, in wrapped
    return loop.run_until_complete(inner)
           ~~~~~~~~~~~~~~~~~~~~~~~^^^^^^^
  File "C:\Users\Hadi\AppData\Local\Programs\Python\Python313\Lib\asyncio\base_events.py", line 719, in run_until_complete
    return future.result()
           ~~~~~~~~~~~~~^^
  File "H:\HadiSadoghiYazdi\CircuitNew\Lib\site-packages\nbclient\client.py", line 709, in async_execute
    await self.async_execute_cell(
        cell, index, execution_count=self.code_cells_executed + 1
    )
  File "H:\HadiSadoghiYazdi\CircuitNew\Lib\site-packages\nbclient\client.py", line 1062, in async_execute_cell
    await self._check_raise_for_error(cell, cell_index, exec_reply)
  File "H:\HadiSadoghiYazdi\CircuitNew\Lib\site-packages\nbclient\client.py", line 918, in _check_raise_for_error
    raise CellExecutionError.from_cell_and_msg(cell, exec_reply_content)
nbclient.exceptions.CellExecutionError: An error occurred while executing the following cell:
------------------
import PySpice.Logging.Logging as Logging
logger = Logging.setup_logging()

from PySpice.Spice.Netlist import Circuit
from PySpice.Unit import *

circuit = Circuit('Independent Voltage Sources')

circuit.V(1, 'A', circuit.gnd, 15@u_V)  # V1 = 15V
circuit.R(1, 'A', 'B', 1@u_Î©)           # R1 = 1Î©
circuit.V(2, 'C', 'B', 10@u_V)          # V2 = 10V
circuit.R(2, 'C', circuit.gnd, 2@u_Î©)   # R2 = 2Î©

simulator = circuit.simulator(temperature=25, nominal_temperature=25)
analysis = simulator.operating_point()

voltage_A = float(analysis['A'][0])
voltage_B = float(analysis['B'][0])
voltage_C = float(analysis['C'][0])

print(f"Voltage at Node A (V1 output): {voltage_A:.2f} V")
print(f"Voltage at Node B (between V1 and V2): {voltage_B:.2f} V")
print(f"Voltage at Node C (V2 output): {voltage_C:.2f} V")
------------------


[31m---------------------------------------------------------------------------[39m
[31mModuleNotFoundError[39m                       Traceback (most recent call last)
[36mCell[39m[36m [39m[32mIn[2][39m[32m, line 1[39m
[32m----> [39m[32m1[39m [38;5;28;01mimport[39;00m[38;5;250m [39m[34;01mPySpice[39;00m[34;01m.[39;00m[34;01mLogging[39;00m[34;01m.[39;00m[34;01mLogging[39;00m[38;5;250m [39m[38;5;28;01mas[39;00m[38;5;250m [39m[34;01mLogging[39;00m
[32m      2[39m logger = Logging.setup_logging()
[32m      4[39m [38;5;28;01mfrom[39;00m[38;5;250m [39m[34;01mPySpice[39;00m[34;01m.[39;00m[34;01mSpice[39;00m[34;01m.[39;00m[34;01mNetlist[39;00m[38;5;250m [39m[38;5;28;01mimport[39;00m Circuit

[31mModuleNotFoundError[39m: No module named 'PySpice'

